<robot name="labrob">
  <!-- Base link -->
  <link name="base_link">
    <visual>
      <origin xyz="0 0 0" rpy="0 0 0" />
      <geometry>
          <box size="1 0.5 0.25"/>
      </geometry>
    </visual>
  </link>
  <!-- Front Right Wheel -->
  <link name="f_r_wheel">
    <visual>
      <origin xyz="0 0 0" rpy="1.570795 0 0" />
      <geometry>
          <cylinder length="0.1" radius="0.2" />
      </geometry>
    </visual>
  </link>
  <joint name="joint_f_r_wheel" type="continuous">
    <parent link="base_link"/>
    <child link="f_r_wheel"/>
    <origin xyz="0.25 -0.30 0" rpy="0 0 0" /> 
    <axis xyz="0 1 0" rpy="0 0 0" />
  </joint>  
  <!-- Back Right Wheel -->
  <link name="b_r_wheel">
    <visual>
      <origin xyz="0 0 0" rpy="1.570795 0 0" />
      <geometry>
          <cylinder length="0.1" radius="0.2" />
      </geometry>
    </visual>
  </link>
  <joint name="joint_b_r_wheel" type="continuous">
    <parent link="base_link"/>
    <child link="b_r_wheel"/>
    <origin xyz="-0.25 -0.30 0" rpy="0 0 0" /> 
    <axis xyz="0 1 0" rpy="0 0 0" />
  </joint>  
  <!-- Front Left Wheel -->
  <link name="f_l_wheel">
    <visual>
      <origin xyz="0 0 0" rpy="1.570795 0 0" />
      <geometry>
          <cylinder length="0.1" radius="0.2" />
      </geometry>
    </visual>
  </link>
  <joint name="joint_f_l_wheel" type="continuous">
    <parent link="base_link"/>
    <child link="f_l_wheel"/>
    <origin xyz="0.25 0.30 0" rpy="0 0 0" /> 
    <axis xyz="0 1 0" rpy="0 0 0" />
  </joint>
  <!-- Back Left Wheel -->
  <link name="b_l_wheel">
    <visual>
      <origin xyz="0 0 0" rpy="1.570795 0 0" />
      <geometry>
          <cylinder length="0.1" radius="0.2" />
      </geometry>
    </visual>
  </link>
  <joint name="joint_b_l_wheel" type="continuous">
    <parent link="base_link"/>
    <child link="b_l_wheel"/>
    <origin xyz="-0.25 0.30 0" rpy="0 0 0" /> 
    <axis xyz="0 1 0" rpy="0 0 0" />
  </joint>
</robot>
